Workbook
Name Slicer_Date_Hierarchy: #N/A
Name Slicer_Region: #N/A
Name Slicer_Status: #N/A

Sheet Dashboard
AU23: #5E82A6
AX47: #96ADC4

Sheet Analysis
A1: Total Revenue By Region
A2: East | B2: =SUMIFS(Table1[Net Revenue],Table1[Region],"East",Table1[Status],"Completed") -> 153956200 | E2: Insights | I2: KPIs
A3: West | B3: =SUMIFS(Table1[Net Revenue],Table1[Region],"West",Table1[Status],"Completed") -> 63334700 | E3: Revenue By Region | I3: Revenue | K3: Orders
A4: North | B4: =SUMIFS(Table1[Net Revenue],Table1[Region],"North",Table1[Status],"Completed") -> 146717750 | E4: Row Labels | F4: Total Revenue | I4: Total Revenue | K4: Total Orders | M4: AOV | O4: Return Rate | Q4: Qty Sold | S4: Total Discount
A5: South | B5: =SUMIFS(Table1[Net Revenue],Table1[Region],"South",Table1[Status],"Completed") -> 98893650 | E5: East | F5: 153956200 | I5: 462902300 | K5: 424 | M5: 1718994.2 | O5: 0.23474178 | Q5: 2867 | S5: 35825700
E6: North | F6: 146717750
A7: Count Of Completed Orders By Sales Rep | E7: South | F7: 98893650
A8: Yemi Osinbajo | B8: =COUNTIFS(Table1[Status],"Completed",Table1[Sales Rep],"Yemi Osinbajo") -> 30 | E8: West | F8: 63334700
A9: Fatima Aliyu | B9: =COUNTIFS(Table1[Status],"Completed",Table1[Sales Rep],"Fatima Aliyu") -> 32 | E9: Grand Total | F9: 462902300 | I9: =I5 -> 462902300 | K9: =K5 -> 424 | M9: =M5 -> 1718994.2 | O9: =O5 -> 0.23474178 | Q9: =Q5 -> 2867 | S9: =S5 -> 35825700
A10: James Okafor | B10: =COUNTIFS(Table1[Status],"Completed",Table1[Sales Rep],"James Okafor") -> 20
A11: Ngozi Adeyemi | B11: =COUNTIFS(Table1[Status],"Completed",Table1[Sales Rep],"Ngozi Adeyemi") -> 29
A12: Emeka Nwosu | B12: =COUNTIFS(Table1[Status],"Completed",Table1[Sales Rep],"Emeka Nwosu") -> 28 | E12: Monthly Revenue Trend
A13: Ibrahim Musa | B13: =COUNTIFS(Table1[Status],"Completed",Table1[Sales Rep],"Ibrahim Musa") -> 22 | E13: Row Labels | F13: Total Revenue
A14: Tunde Fashola | B14: =COUNTIFS(Table1[Status],"Completed",Table1[Sales Rep],"Tunde Fashola") -> 28 | E14: Jan | F14: 49635800
A15: Amaka Bello | B15: =COUNTIFS(Table1[Status],"Completed",Table1[Sales Rep],"Amaka Bello") -> 23 | E15: Feb | F15: 20624150
A16: Kemi Adebayo | B16: =COUNTIFS(Table1[Status],"Completed",Table1[Sales Rep],"Kemi Adebayo") -> 24 | E16: Mar | F16: 53819600
A17: Chukwudi Eze | B17: =COUNTIFS(Table1[Status],"Completed",Table1[Sales Rep],"Chukwudi Eze") -> 22 | E17: Apr | F17: 37960500
E18: May | F18: 19575650
A19: Avg Unit Price For Electronics In the North Region | E19: Jun | F19: 40644250
A20: =AVERAGEIFS(Table1[Unit Price Clean],Table1[Category],"Accessories",Table1[Region],"North") -> 24847.458 | E20: Jul | F20: 34914400
E21: Aug | F21: 46695850
A22: Weighted Average Discount Across all Orders | E22: Sept | F22: 35852750
A23: =AVERAGE(Table1[Discount]) -> 139738.76 | E23: Oct | F23: 54232000
E24: Nov | F24: 28664000
A25: Top 5 Orders | E25: Dec | F25: 40283350
A26: =LARGE(Table1[Net Revenue],5) -> 8550000 | E26: Grand Total | F26: 462902300
A28: Bottom 5 Revenue Orders | E28: Revenue By Channel
A29: =SMALL(Table1[Net Revenue],5) -> 22400 | E29: Row Labels | F29: Total Revenue
E30: Distributor | F30: 99967000
E31: In-Store | F31: 202267050
E32: Online | F32: 156840250
E36: Top 5 Revenue By Sales Rep
E37: Row Labels | F37: Total Revenue
E38: Fatima Aliyu | F38: 43671400
E39: Amaka Bello | F39: 50752150
E40: Ngozi Adeyemi | F40: 52015100
E41: Emeka Nwosu | F41: 60132500
E42: Yemi Osinbajo | F42: 63432700
E44: Status By Orders
E45: Row Labels | F45: Total Orders
...

Sheet Pivot Table
A2: Revenue By Sales Rep and Region
A3: Total Revenue | B3: Column Labels
A4: Row Labels | B4: East | C4: North | D4: South | E4: West | F4: Grand Total
A5: Amaka Bello | B5: 14885600 | C5: 13800650 | D5: 13880400 | E5: 8185500 | F5: 50752150
A6: Chukwudi Eze | B6: 14858600 | C6: 3647300 | D6: 4613600 | E6: 546000 | F6: 23665500
A7: Emeka Nwosu | B7: 20403000 | C7: 11418200 | D7: 10578500 | E7: 17732800 | F7: 60132500
A8: Fatima Aliyu | B8: 16973750 | C8: 17167700 | D8: 6720950 | E8: 2809000 | F8: 43671400
A9: Ibrahim Musa | B9: 13409750 | C9: 25344400 | D9: 5352000 | E9: 1403200 | F9: 45509350
A10: James Okafor | B10: 5470600 | C10: 13855750 | D10: 9576000 | E10: 7164000 | F10: 36066350
A11: Kemi Adebayo | B11: 28076000 | C11: 15844500 | D11: 11539400 | E11: 89600 | F11: 55549500
A12: N/A | C12: 324000 | D12: 2907000 | E12: 3060000 | F12: 6291000
A13: Ngozi Adeyemi | B13: 12344500 | C13: 18571100 | D13: 5945900 | E13: 15153600 | F13: 52015100
A14: Tunde Fashola | B14: 3571900 | C14: 14793450 | D14: 920400 | E14: 6531000 | F14: 25816750
A15: Yemi Osinbajo | B15: 23962500 | C15: 11950700 | D15: 26859500 | E15: 660000 | F15: 63432700
A16: Grand Total | B16: 153956200 | C16: 146717750 | D16: 98893650 | E16: 63334700 | F16: 462902300
A18: Product Insights
A19: Row Labels | B19: Count of Order ID | C19: Sum of Unit Price Clean | D19: Qty Sold
A20: Keyboard Mech | B20: 44 | C20: 1232000 | D20: 310
A21: Laptop Pro | B21: 86 | C21: 38700000 | D21: 628
A22: Monitor 4K | B22: 47 | C22: 4465000 | D22: 243
A23: Mouse Ergo | B23: 51 | C23: 918000 | D23: 286
A24: SmartPhone X | B24: 65 | C24: 14300000 | D24: 426
A25: Tablet Air | B25: 51 | C25: 9180000 | D25: 385
A26: Webcam HD | B26: 46 | C26: 1012000 | D26: 340
A27: Wireless Earbuds | B27: 36 | C27: 1260000 | D27: 249
A28: Grand Total | B28: 426 | C28: 71067000 | D28: 2867
A30: Monthly Revenue By Channel
A31: Total Revenue | B31: Column Labels
A32: Row Labels | B32: Distributor | C32: In-Store | D32: Online | E32: N/A | F32: Grand Total
A33: January | B33: 8653200 | C33: 16532100 | D33: 24450500 | F33: 49635800
A34: February | B34: 13359400 | C34: 5095750 | D34: 2169000 | F34: 20624150
A35: March | B35: 6368600 | C35: 28919750 | D35: 18531250 | F35: 53819600
A36: April | B36: 8246100 | C36: 19848000 | D36: 9866400 | F36: 37960500
A37: May | B37: 1829100 | C37: 5428500 | D37: 10338050 | E37: 1980000 | F37: 19575650
A38: June | B38: 11848000 | C38: 17334250 | D38: 11462000 | F38: 40644250
A39: July | B39: 13660400 | C39: 14699000 | D39: 6467000 | E39: 88000 | F39: 34914400
A40: August | B40: 11542100 | C40: 33716650 | D40: 1437100 | F40: 46695850
A41: September | B41: 4538400 | C41: 13445750 | D41: 17868600 | F41: 35852750
A42: October | B42: 5972000 | C42: 21199500 | D42: 27060500 | F42: 54232000
A43: November | B43: 4191500 | C43: 9371000 | D43: 13341500 | E43: 1760000 | F43: 28664000
...

Sheet Clean Raw Data
A1: Order ID | B1: Order Date | C1: Customer ID | D1: Sales Rep | E1: Region | F1: Product | G1: Category | H1: Channel | I1: Quantity | J1: Unit Price (₦) | K1: Unit Price Clean | L1: Revenue | M1: Discount (%) | N1: Discount | O1: Net Revenue | P1: Status | Q1: Product_Clean | R1: Category_Clean | S1: Channel_Clean
A2: ORD-47512 | B2: 45434 | C2: CUST-4094 | D2: Yemi Osinbajo | E2: East | F2: Wireless Earbuds | G2: Accessories | H2: Distributor | I2: 7 | J2: 35000 | K2: =J2 -> 35000 | L2: =I2*K2 -> 245000 | M2: 10 | N2: =M2/100 * L2 -> 24500 | O2: =L2-N2 -> 220500 | P2: Pending | Q2: Wireless Earbuds | R2: Accessories | S2: Distributor
A3: ORD-67431 | B3: 45464 | C3: CUST-1447 | D3: Fatima Aliyu | E3: North | F3: Mouse Ergo | G3: Accessories | H3: Distributor | I3: 4 | J3: 18000 | K3: =J3 -> 18000 | L3: =I3*K3 -> 72000 | M3: 0 | N3: =M3/100 * L3 -> 0 | O3: =L3-N3 -> 72000 | P3: Completed | Q3: Mouse Ergo | R3: Accessories | S3: Distributor
A4: ORD-89777 | B4: 45513 | C4: CUST-4674 | D4: James Okafor | E4: West | F4: Keyboard Mech | G4: Accessories | H4: Distributor | I4: 2 | J4: 28000 | K4: =J4 -> 28000 | L4: =I4*K4 -> 56000 | M4: 15 | N4: =M4/100 * L4 -> 8400 | O4: =L4-N4 -> 47600 | P4: Pending | Q4: Keyboard Mech | R4: Accessories | S4: Distributor
A5: ORD-84141 | B5: 45573 | C5: CUST-1120 | D5: Fatima Aliyu | E5: West | F5: Webcam HD | G5: Accessories | H5: Distributor | I5: 1 | J5: 22000 | K5: =J5 -> 22000 | L5: =I5*K5 -> 22000 | M5: 0 | N5: =M5/100 * L5 -> 0 | O5: =L5-N5 -> 22000 | P5: Completed | Q5: Webcam HD | R5: Accessories | S5: Distributor
A6: ORD-72684 | B6: 45492 | C6: CUST-2977 | D6: Chukwudi Eze | E6: North | F6: Keyboard Mech | G6: Accessories | H6: In-Store | I6: 6 | J6: 28000 | K6: =J6 -> 28000 | L6: =I6*K6 -> 168000 | M6: 0 | N6: =M6/100 * L6 -> 0 | O6: =L6-N6 -> 168000 | P6: Completed | Q6: Keyboard Mech | R6: Accessories | S6: In-Store
A7: ORD-88636 | B7: 45604 | C7: CUST-1008 | D7: Fatima Aliyu | E7: South | F7: Mouse Ergo | G7: Accessories | H7: Online | I7: 4 | J7: 18000 | K7: =J7 -> 18000 | L7: =I7*K7 -> 72000 | M7: 20 | N7: =M7/100 * L7 -> 14400 | O7: =L7-N7 -> 57600 | P7: Completed | Q7: Mouse Ergo | R7: Accessories | S7: Online
A8: ORD-98754 | B8: 45488 | C8: CUST-1949 | D8: Ngozi Adeyemi | E8: North | F8: Tablet Air | G8: Electronics | H8: In-Store | I8: 11 | J8: 180000 | K8: =J8 -> 180000 | L8: =I8*K8 -> 1980000 | M8: 10 | N8: =M8/100 * L8 -> 198000 | O8: =L8-N8 -> 1782000 | P8: Completed | Q8: Tablet Air | R8: Electronics | S8: In-Store
A9: ORD-27224 | B9: 45547 | C9: CUST-3174 | D9: Emeka Nwosu | E9: East | F9: SmartPhone X | G9: Electronics | H9: Online | I9: 7 | J9: 220000 | K9: =J9 -> 220000 | L9: =I9*K9 -> 1540000 | M9: 0 | N9: =M9/100 * L9 -> 0 | O9: =L9-N9 -> 1540000 | P9: Completed | Q9: SmartPhone X | R9: Electronics | S9: Online
A10: ORD-64948 | B10: 45478 | C10: CUST-3751 | D10: Fatima Aliyu | E10: East | F10: Webcam HD | G10: Accessories | H10: In-Store | I10: 8 | J10: 22000 | K10: =J10 -> 22000 | L10: =I10*K10 -> 176000 | M10: 0 | N10: =M10/100 * L10 -> 0 | O10: =L10-N10 -> 176000 | P10: Cancelled | Q10: Webcam HD | R10: Accessories | S10: In-Store
A11: ORD-68459 | B11: 45491 | C11: CUST-2962 | D11: N/A | E11: N/A | F11: Tablet Air | G11: Electronics | H11: In-Store | I11: 10 | J11: 180000 | K11: =J11 -> 180000 | L11: =I11*K11 -> 1800000 | M11: 5 | N11: =M11/100 * L11 -> 90000 | O11: =L11-N11 -> 1710000 | P11: Pending | Q11: Tablet Air | R11: Electronics | S11: In-Store
A12: ORD-26406 | B12: 45357 | C12: CUST-3698 | D12: Yemi Osinbajo | E12: North | F12: Laptop Pro | G12: Electronics | H12: Online | I12: 19 | J12: 450000 | K12: =J12 -> 450000 | L12: =I12*K12 -> 8550000 | M12: 10 | N12: =M12/100 * L12 -> 855000 | O12: =L12-N12 -> 7695000 | P12: Completed | Q12: Laptop Pro | R12: Electronics | S12: Online
A13: ORD-99016 | B13: 45304 | C13: CUST-3424 | D13: Chukwudi Eze | E13: East | F13: Keyboard Mech | G13: Accessories | H13: Online | I13: 20 | J13: 28000 | K13: =J13 -> 28000 | L13: =I13*K13 -> 560000 | M13: 10 | N13: =M13/100 * L13 -> 56000 | O13: =L13-N13 -> 504000 | P13: Completed | Q13: Keyboard Mech | R13: Accessories | S13: Online
... A82: ORD-74451 | B82: 45350 | C82: CUST-1658 | D82: Kemi Adebayo | E82: East | F82: SmartPhone X | G82: Electronics | H82: online | I82: 11 | J82: 220000 | K82: =J82 -> 220000 | L82: =I82*K82 -> 2420000 | M82: 15 | N82: =M82/100 * L82 -> 363000 | O82: =L82-N82 -> 2057000 | P82: Cancelled | Q82: SmartPhone X | R82: Electronics | S82: online
A83: ORD-96772 | B83: 45415 | C83: CUST-2939 | D83: Ngozi Adeyemi | E83: North | F83: Mouse Ergo | G83: Accessories | H83: online | I83: 6 | J83: 1 | K83: 18000 | L83: =I83*K83 -> 108000 | M83: 15 | N83: =M83/100 * L83 -> 16200 | O83: =L83-N83 -> 91800 | P83: Pending | Q83: Mouse Ergo | R83: Accessories | S83: online
A84: ORD-52291 | B84: 45614 | C84: CUST-2124 | D84: Fatima Aliyu | E84: North | F84: Wireless Earbuds | G84: Accessories | H84: Distributor | I84: 9 | J84: 35000 | K84: =J84 -> 35000 | L84: =I84*K84 -> 315000 | M84: 0 | N84: =M84/100 * L84 -> 0 | O84: =L84-N84 -> 315000 | P84: Completed | Q84: Wireless Earbuds | R84: Accessories | S84: Distributor
A85: ORD-93748 | B85: 45405 | C85: CUST-1588 | D85: Amaka Bello | E85: North | F85: Mouse Ergo | G85: Accessories | H85: Online | I85: 17 | J85: 18000 | K85: =J85 -> 18000 | L85: =I85*K85 -> 306000 | M85: 10 | N85: =M85/100 * L85 -> 30600 | O85: =L85-N85 -> 275400 | P85: Completed | Q85: Mouse Ergo | R85: Accessories | S85: Online
A86: ORD-63090 | B86: 45572 | C86: CUST-2841 | D86: Chukwudi Eze | E86: South | F86: Tablet Air | G86: Electronics | H86: Online | I86: 1 | J86: 180000 | K86: =J86 -> 180000 | L86: =I86*K86 -> 180000 | M86: 15 | N86: =M86/100 * L86 -> 27000 | O86: =L86-N86 -> 153000 | P86: Completed | Q86: Tablet Air | R86: Electronics | S86: Online
A87: ORD-99764 | B87: 45640 | C87: CUST-3477 | D87: Ngozi Adeyemi | E87: South | F87: SmartPhone X | G87: Electronics | H87: Distributor | I87: 11 | J87: 220000 | K87: =J87 -> 220000 | L87: =I87*K87 -> 2420000 | M87: 0 | N87: =M87/100 * L87 -> 0 | O87: =L87-N87 -> 2420000 | P87: Completed | Q87: SmartPhone X | R87: Electronics | S87: Distributor
A88: ORD-45358 | B88: 45552 | C88: CUST-2671 | D88: Chukwudi Eze | E88: North | F88: SmartPhone X | G88: Electronics | H88: In-Store | I88: 15 | J88: 220000 | K88: =J88 -> 220000 | L88: =I88*K88 -> 3300000 | M88: 10 | N88: =M88/100 * L88 -> 330000 | O88: =L88-N88 -> 2970000 | P88: Completed | Q88: SmartPhone X | R88: Electronics | S88: In-Store
A89: ORD-12872 | B89: 45437 | C89: CUST-3190 | D89: Chukwudi Eze | E89: North | F89: Webcam HD | G89: Accessories | H89: Distributor | I89: 13 | J89: 22000 | K89: =J89 -> 22000 | L89: =I89*K89 -> 286000 | M89: 15 | N89: =M89/100 * L89 -> 42900 | O89: =L89-N89 -> 243100 | P89: Completed | Q89: Webcam HD | R89: Accessories | S89: Distributor
A90: ORD-63271 | B90: 45294 | C90: CUST-2205 | D90: Tunde Fashola | E90: East | F90: Mouse Ergo | G90: Accessories | H90: In-Store | I90: 16 | J90: 18000 | K90: =J90 -> 18000 | L90: =I90*K90 -> 288000 | M90: 5 | N90: =M90/100 * L90 -> 14400 | O90: =L90-N90 -> 273600 | P90: Completed | Q90: Mouse Ergo | R90: Accessories | S90: In-Store
A91: ORD-41133 | B91: 45438 | C91: CUST-4212 | D91: Yemi Osinbajo | E91: East | F91: Mouse Ergo | G91: Accessories | H91: Online | I91: 18 | J91: 18000 | K91: =J91 -> 18000 | L91: =I91*K91 -> 324000 | M91: 0 | N91: =M91/100 * L91 -> 0 | O91: =L91-N91 -> 324000 | P91: Pending | Q91: Mouse Ergo | R91: Accessories | S91: Online
A92: ORD-61773 | B92: 45360 | C92: CUST-2146 | D92: James Okafor | E92: West | F92: Mouse Ergo | G92: Accessories | H92: Online | I92: 12 | J92: 18000 | K92: =J92 -> 18000 | L92: =I92*K92 -> 216000 | M92: 0 | N92: =M92/100 * L92 -> 0 | O92: =L92-N92 -> 216000 | P92: Completed | Q92: Mouse Ergo | R92: Accessories | S92: On-Line
A93: ORD-75333 | B93: 45475 | C93: CUST-3282 | D93: Fatima Aliyu | E93: North | F93: Mouse Ergo | G93: Accessories | H93: Online | I93: 4 | J93: 18000 | K93: =J93 -> 18000 | L93: =I93*K93 -> 72000 | M93: 5 | N93: =M93/100 * L93 -> 3600 | O93: =L93-N93 -> 68400 | P93: Completed | Q93: Mouse Ergo | R93: Accessories | S93: Online
A94: ORD-87621 | B94: 45652 | C94: CUST-4260 | D94: Ibrahim Musa | E94: North | F94: Keyboard Mech | G94: Accessories | H94: In-Store | I94: 9 | J94: 28000 | K94: =J94 -> 28000 | L94: =I94*K94 -> 252000 | M94: 20 | N94: =M94/100 * L94 -> 50400 | O94: =L94-N94 -> 201600 | P94: Pending | Q94: Keyboard Mech | R94: Accessories | S94: In-Store
A95: ORD-24996 | B95: 45517 | C95: CUST-2703 | D95: Ngozi Adeyemi | E95: West | F95: Webcam HD | G95: Accessories | H95: Online | I95: 14 | J95: 22000 | K95: =J95 -> 22000 | L95: =I95*K95 -> 308000 | M95: 0 | N95: =M95/100 * L95 -> 0 | O95: =L95-N95 -> 308000 | P95: Pending | Q95: Webcam HD | R95: Accessories | S95: Online
... A120: ORD-64732 | B120: 45398 | C120: CUST-3255 | D120: Chukwudi Eze | E120: South | F120: Laptop Pro | G120: Electronics | H120: Distributor | I120: 13 | J120: 450000 | K120: =J120 -> 450000 | L120: =I120*K120 -> 5850000 | M120: 10 | N120: =M120/100 * L120 -> 585000 | O120: =L120-N120 -> 5265000 | P120: Pending | Q120: Laptop Pro | R120: Electronics | S120: Distributor
A121: ORD-41278 | B121: 45567 | C121: CUST-2266 | D121: Ngozi Adeyemi | E121: North | F121: Laptop Pro | G121: Electronics | H121: Online | I121: 15 | J121: -5000 | K121: 450000 | L121: =I121*K121 -> 6750000 | M121: 10 | N121: =M121/100 * L121 -> 675000 | O121: =L121-N121 -> 6075000 | P121: Completed | Q121: Laptop Pro | R121: Electronics | S121: Online
A122: ORD-25572 | B122: 45358 | C122: CUST-3467 | D122: Amaka Bello | E122: West | F122: Tablet Air | G122: Electronics | H122: Distributor | I122: 18 | J122: 180000 | K122: =J122 -> 180000 | L122: =I122*K122 -> 3240000 | M122: 0 | N122: =M122/100 * L122 -> 0 | O122: =L122-N122 -> 3240000 | P122: Cancelled | Q122: Tablet Air | R122: Electronics | S122: Distributor
A123: ORD-46002 | B123: 45293 | C123: CUST-2510 | D123: Fatima Aliyu | E123: North | F123: Laptop Pro | G123: Electronics | H123: Online | I123: 15 | J123: 450000 | K123: =J123 -> 450000 | L123: =I123*K123 -> 6750000 | M123: 5 | N123: =M123/100 * L123 -> 337500 | O123: =L123-N123 -> 6412500 | P123: Returned | Q123: Laptop Pro | R123: Electronics | S123: Online
A124: ORD-96752 | B124: 45644 | C124: CUST-1249 | D124: Chukwudi Eze | E124: South | F124: Mouse Ergo | G124: Accessories | H124: Distributor | I124: 2 | J124: 18000 | K124: =J124 -> 18000 | L124: =I124*K124 -> 36000 | M124: 10 | N124: =M124/100 * L124 -> 3600 | O124: =L124-N124 -> 32400 | P124: Pending | Q124: Mouse Ergo | R124: Accessories | S124: Distributor
A125: ORD-46512 | B125: 45635 | C125: CUST-1118 | D125: Ibrahim Musa | E125: East | F125: Wireless Earbuds | G125: Accessories | H125: In-Store | I125: 20 | J125: 35000 | K125: =J125 -> 35000 | L125: =I125*K125 -> 700000 | M125: 15 | N125: =M125/100 * L125 -> 105000 | O125: =L125-N125 -> 595000 | P125: Completed | Q125: Wireless Earbuds | R125: Accessories | S125: In-Store
A126: ORD-35415 | B126: 45419 | C126: CUST-1710 | D126: Fatima Aliyu | E126: South | F126: Monitor 4K | G126: Electronics | H126: In-Store | I126: 4 | J126: 95000 | K126: =J126 -> 95000 | L126: =I126*K126 -> 380000 | M126: 0 | N126: =M126/100 * L126 -> 0 | O126: =L126-N126 -> 380000 | P126: Pending | Q126: Monitor 4K | R126: Electronics | S126: In-Store
A127: ORD-43980 | B127: 45482 | C127: CUST-3145 | D127: Fatima Aliyu | E127: South | F127: Tablet Air | G127: Electronics | H127: Distributor | I127: 1 | J127: 180000 | K127: =J127 -> 180000 | L127: =I127*K127 -> 180000 | M127: 0 | N127: =M127/100 * L127 -> 0 | O127: =L127-N127 -> 180000 | P127: Completed | Q127: Tablet Air | R127: Electronics | S127: Distributor
A128: ORD-86344 | B128: 45337 | C128: CUST-2256 | D128: Emeka Nwosu | E128: South | F128: Laptop Pro | G128: Electronics | H128: Distributor | I128: 2 | J128: 450000 | K128: =J128 -> 450000 | L128: =I128*K128 -> 900000 | M128: 15 | N128: =M128/100 * L128 -> 135000 | O128: =L128-N128 -> 765000 | P128: Pending | Q128: Laptop Pro | R128: Electronics | S128: Distributor
A129: ORD-62550 | B129: 45550 | C129: CUST-1032 | D129: Kemi Adebayo | E129: East | F129: SmartPhone X | G129: Electronics | H129: Distributor | I129: 11 | J129: 220000 | K129: =J129 -> 220000 | L129: =I129*K129 -> 2420000 | M129: 0 | N129: =M129/100 * L129 -> 0 | O129: =L129-N129 -> 2420000 | P129: Returned | Q129: SmartPhone X | R129: Electronics | S129: Distributor
A130: ORD-67014 | B130: 45637 | C130: CUST-2302 | D130: Ngozi Adeyemi | E130: East | F130: Tablet Air | G130: Electronics | H130: Distributor | I130: 13 | J130: 180000 | K130: =J130 -> 180000 | L130: =I130*K130 -> 2340000 | M130: 15 | N130: =M130/100 * L130 -> 351000 | O130: =L130-N130 -> 1989000 | P130: Cancelled | Q130: Tablet Air | R130: Electronics | S130: Distributor
A131: ORD-67261 | B131: 45592 | C131: CUST-1718 | D131: Fatima Aliyu | E131: South | F131: Mouse Ergo | G131: Accessories | H131: In-Store | I131: 8 | J131: 18000 | K131: =J131 -> 18000 | L131: =I131*K131 -> 144000 | M131: 15 | N131: =M131/100 * L131 -> 21600 | O131: =L131-N131 -> 122400 | P131: Cancelled | Q131: Mouse Ergo | R131: Accessories | S131: In-Store
A132: ORD-59797 | B132: 45522 | C132: CUST-1511 | D132: Fatima Aliyu | E132: East | F132: SmartPhone X | G132: Electronics | H132: Distributor | I132: 2 | J132: 220000 | K132: =J132 -> 220000 | L132: =I132*K132 -> 440000 | M132: 15 | N132: =M132/100 * L132 -> 66000 | O132: =L132-N132 -> 374000 | P132: Returned | Q132: SmartPhone X | R132: Electronics | S132: Distributor
...

Sheet Clean Calc Table
A1: Order ID | B1: Product | C1: Quantity | D1: Unit Price (₦) | E1: Discount (%) | F1: Status | G1: Revenue (₦) | H1: Discounted Revenue (₦) | I1: VAT 7.5% (₦) | J1: Net Revenue (₦) | K1: Category (XLOOKUP) | L1: Supplier Name | M1: Warranty (INDEX-MATCH) | N1: SKU
A2: ORD-47512 | B2: Wireless Earbuds | C2: 7 | D2: 35000 | E2: 10 | F2: Pending | G2: =C2*D2 -> 245000 | H2: =G2*(1-E2/100) -> 220500 | I2: =H2*0.075 -> 16537.5 | J2: =H2+I2 -> 237037.5 | K2: =IFERROR(_xlfn.XLOOKUP(B:B,LOOKUP_TABLES!A:A,LOOKUP_TABLES!B:B),"Not Found") -> Accessories | L2: =IFERROR(_xlfn.XLOOKUP(M:M,LOOKUP_TABLES!E:E,LOOKUP_TABLES!D:D),"Not Found") -> SoundWave Co | M2: =IFERROR(INDEX(LOOKUP_TABLES!E:E,MATCH(B2,LOOKUP_TABLES!A:A,0)),"Not Found") -> 6 | N2: =_xlfn.XLOOKUP(B:B,LOOKUP_TABLES!A:A,LOOKUP_TABLES!F:F) -> SKU-1003
A3: ORD-67431 | B3: Mouse Ergo | C3: 4 | D3: 18000 | E3: 0 | F3: Completed | G3: =C3*D3 -> 72000 | H3: =G3*(1-E3/100) -> 72000 | I3: =H3*0.075 -> 5400 | J3: =H3+I3 -> 77400 | K3: =IFERROR(_xlfn.XLOOKUP(B:B,LOOKUP_TABLES!A:A,LOOKUP_TABLES!B:B),"Not Found") -> Accessories | L3: =IFERROR(_xlfn.XLOOKUP(M:M,LOOKUP_TABLES!E:E,LOOKUP_TABLES!D:D),"Not Found") -> MobileMaster NG | M3: =IFERROR(INDEX(LOOKUP_TABLES!E:E,MATCH(B3,LOOKUP_TABLES!A:A,0)),"Not Found") -> 12 | N3: =_xlfn.XLOOKUP(B:B,LOOKUP_TABLES!A:A,LOOKUP_TABLES!F:F) -> SKU-1006
A4: ORD-89777 | B4: Keyboard Mech | C4: 2 | D4: 28000 | E4: 15 | F4: Pending | G4: =C4*D4 -> 56000 | H4: =G4*(1-E4/100) -> 47600 | I4: =H4*0.075 -> 3570 | J4: =H4+I4 -> 51170 | K4: =IFERROR(_xlfn.XLOOKUP(B:B,LOOKUP_TABLES!A:A,LOOKUP_TABLES!B:B),"Not Found") -> Accessories | L4: =IFERROR(_xlfn.XLOOKUP(M:M,LOOKUP_TABLES!E:E,LOOKUP_TABLES!D:D),"Not Found") -> MobileMaster NG | M4: =IFERROR(INDEX(LOOKUP_TABLES!E:E,MATCH(B4,LOOKUP_TABLES!A:A,0)),"Not Found") -> 12 | N4: =_xlfn.XLOOKUP(B:B,LOOKUP_TABLES!A:A,LOOKUP_TABLES!F:F) -> SKU-1005
A5: ORD-84141 | B5: Webcam HD | C5: 1 | D5: 22000 | E5: 0 | F5: Completed | G5: =C5*D5 -> 22000 | H5: =G5*(1-E5/100) -> 22000 | I5: =H5*0.075 -> 1650 | J5: =H5+I5 -> 23650 | K5: =IFERROR(_xlfn.XLOOKUP(B:B,LOOKUP_TABLES!A:A,LOOKUP_TABLES!B:B),"Not Found") -> Accessories | L5: =IFERROR(_xlfn.XLOOKUP(M:M,LOOKUP_TABLES!E:E,LOOKUP_TABLES!D:D),"Not Found") -> MobileMaster NG | M5: =IFERROR(INDEX(LOOKUP_TABLES!E:E,MATCH(B5,LOOKUP_TABLES!A:A,0)),"Not Found") -> 12 | N5: =_xlfn.XLOOKUP(B:B,LOOKUP_TABLES!A:A,LOOKUP_TABLES!F:F) -> SKU-1007
A6: ORD-72684 | B6: Keyboard Mech | C6: 6 | D6: 28000 | E6: 0 | F6: Completed | G6: =C6*D6 -> 168000 | H6: =G6*(1-E6/100) -> 168000 | I6: =H6*0.075 -> 12600 | J6: =H6+I6 -> 180600 | K6: =IFERROR(_xlfn.XLOOKUP(B:B,LOOKUP_TABLES!A:A,LOOKUP_TABLES!B:B),"Not Found") -> Accessories | L6: =IFERROR(_xlfn.XLOOKUP(M:M,LOOKUP_TABLES!E:E,LOOKUP_TABLES!D:D),"Not Found") -> MobileMaster NG | M6: =IFERROR(INDEX(LOOKUP_TABLES!E:E,MATCH(B6,LOOKUP_TABLES!A:A,0)),"Not Found") -> 12 | N6: =_xlfn.XLOOKUP(B:B,LOOKUP_TABLES!A:A,LOOKUP_TABLES!F:F) -> SKU-1005
A7: ORD-88636 | B7: Mouse Ergo | C7: 4 | D7: 18000 | E7: 20 | F7: Completed | G7: =C7*D7 -> 72000 | H7: =G7*(1-E7/100) -> 57600 | I7: =H7*0.075 -> 4320 | J7: =H7+I7 -> 61920 | K7: =IFERROR(_xlfn.XLOOKUP(B:B,LOOKUP_TABLES!A:A,LOOKUP_TABLES!B:B),"Not Found") -> Accessories | L7: =IFERROR(_xlfn.XLOOKUP(M:M,LOOKUP_TABLES!E:E,LOOKUP_TABLES!D:D),"Not Found") -> MobileMaster NG | M7: =IFERROR(INDEX(LOOKUP_TABLES!E:E,MATCH(B7,LOOKUP_TABLES!A:A,0)),"Not Found") -> 12 | N7: =_xlfn.XLOOKUP(B:B,LOOKUP_TABLES!A:A,LOOKUP_TABLES!F:F) -> SKU-1006
A8: ORD-98754 | B8: Tablet Air | C8: 11 | D8: 180000 | E8: 10 | F8: Completed | G8: =C8*D8 -> 1980000 | H8: =G8*(1-E8/100) -> 1782000 | I8: =H8*0.075 -> 133650 | J8: =H8+I8 -> 1915650 | K8: =IFERROR(_xlfn.XLOOKUP(B:B,LOOKUP_TABLES!A:A,LOOKUP_TABLES!B:B),"Not Found") -> Electronics | L8: =IFERROR(_xlfn.XLOOKUP(M:M,LOOKUP_TABLES!E:E,LOOKUP_TABLES!D:D),"Not Found") -> MobileMaster NG | M8: =IFERROR(INDEX(LOOKUP_TABLES!E:E,MATCH(B8,LOOKUP_TABLES!A:A,0)),"Not Found") -> 12 | N8: =_xlfn.XLOOKUP(B:B,LOOKUP_TABLES!A:A,LOOKUP_TABLES!F:F) -> SKU-1002
A9: ORD-27224 | B9: SmartPhone X | C9: 7 | D9: 220000 | E9: 0 | F9: Completed | G9: =C9*D9 -> 1540000 | H9: =G9*(1-E9/100) -> 1540000 | I9: =H9*0.075 -> 115500 | J9: =H9+I9 -> 1655500 | K9: =IFERROR(_xlfn.XLOOKUP(B:B,LOOKUP_TABLES!A:A,LOOKUP_TABLES!B:B),"Not Found") -> Electronics | L9: =IFERROR(_xlfn.XLOOKUP(M:M,LOOKUP_TABLES!E:E,LOOKUP_TABLES!D:D),"Not Found") -> MobileMaster NG | M9: =IFERROR(INDEX(LOOKUP_TABLES!E:E,MATCH(B9,LOOKUP_TABLES!A:A,0)),"Not Found") -> 12 | N9: =_xlfn.XLOOKUP(B:B,LOOKUP_TABLES!A:A,LOOKUP_TABLES!F:F) -> SKU-1001
A10: ORD-64948 | B10: Webcam HD | C10: 8 | D10: 22000 | E10: 0 | F10: Cancelled | G10: =C10*D10 -> 176000 | H10: =G10*(1-E10/100) -> 176000 | I10: =H10*0.075 -> 13200 | J10: =H10+I10 -> 189200 | K10: =IFERROR(_xlfn.XLOOKUP(B:B,LOOKUP_TABLES!A:A,LOOKUP_TABLES!B:B),"Not Found") -> Accessories | L10: =IFERROR(_xlfn.XLOOKUP(M:M,LOOKUP_TABLES!E:E,LOOKUP_TABLES!D:D),"Not Found") -> MobileMaster NG | M10: =IFERROR(INDEX(LOOKUP_TABLES!E:E,MATCH(B10,LOOKUP_TABLES!A:A,0)),"Not Found") -> 12 | N10: =_xlfn.XLOOKUP(B:B,LOOKUP_TABLES!A:A,LOOKUP_TABLES!F:F) -> SKU-1007
A11: ORD-68459 | B11: Tablet Air | C11: 10 | D11: 180000 | E11: 5 | F11: Pending | G11: =C11*D11 -> 1800000 | H11: =G11*(1-E11/100) -> 1710000 | I11: =H11*0.075 -> 128250 | J11: =H11+I11 -> 1838250 | K11: =IFERROR(_xlfn.XLOOKUP(B:B,LOOKUP_TABLES!A:A,LOOKUP_TABLES!B:B),"Not Found") -> Electronics | L11: =IFERROR(_xlfn.XLOOKUP(M:M,LOOKUP_TABLES!E:E,LOOKUP_TABLES!D:D),"Not Found") -> MobileMaster NG | M11: =IFERROR(INDEX(LOOKUP_TABLES!E:E,MATCH(B11,LOOKUP_TABLES!A:A,0)),"Not Found") -> 12 | N11: =_xlfn.XLOOKUP(B:B,LOOKUP_TABLES!A:A,LOOKUP_TABLES!F:F) -> SKU-1002
A12: ORD-26406 | B12: Laptop Pro | C12: 19 | D12: 450000 | E12: 10 | F12: Completed | G12: =C12*D12 -> 8550000 | H12: =G12*(1-E12/100) -> 7695000 | I12: =H12*0.075 -> 577125 | J12: =H12+I12 -> 8272125 | K12: =IFERROR(_xlfn.XLOOKUP(B:B,LOOKUP_TABLES!A:A,LOOKUP_TABLES!B:B),"Not Found") -> Electronics | L12: =IFERROR(_xlfn.XLOOKUP(M:M,LOOKUP_TABLES!E:E,LOOKUP_TABLES!D:D),"Not Found") -> TechGlobal Ltd | M12: =IFERROR(INDEX(LOOKUP_TABLES!E:E,MATCH(B12,LOOKUP_TABLES!A:A,0)),"Not Found") -> 24 | N12: =_xlfn.XLOOKUP(B:B,LOOKUP_TABLES!A:A,LOOKUP_TABLES!F:F) -> SKU-1000
A13: ORD-99016 | B13: Keyboard Mech | C13: 20 | D13: 28000 | E13: 10 | F13: Completed | G13: =C13*D13 -> 560000 | H13: =G13*(1-E13/100) -> 504000 | I13: =H13*0.075 -> 37800 | J13: =H13+I13 -> 541800 | K13: =IFERROR(_xlfn.XLOOKUP(B:B,LOOKUP_TABLES!A:A,LOOKUP_TABLES!B:B),"Not Found") -> Accessories | L13: =IFERROR(_xlfn.XLOOKUP(M:M,LOOKUP_TABLES!E:E,LOOKUP_TABLES!D:D),"Not Found") -> MobileMaster NG | M13: =IFERROR(INDEX(LOOKUP_TABLES!E:E,MATCH(B13,LOOKUP_TABLES!A:A,0)),"Not Found") -> 12 | N13: =_xlfn.XLOOKUP(B:B,LOOKUP_TABLES!A:A,LOOKUP_TABLES!F:F) -> SKU-1005
... A50: ORD-94803 | B50: Laptop Pro | C50: 14 | D50: 450000 | E50: 0 | F50: Cancelled | G50: =C50*D50 -> 6300000 | H50: =G50*(1-E50/100) -> 6300000 | I50: =H50*0.075 -> 472500 | J50: =H50+I50 -> 6772500 | K50: =IFERROR(_xlfn.XLOOKUP(B:B,LOOKUP_TABLES!A:A,LOOKUP_TABLES!B:B),"Not Found") -> Electronics | L50: =IFERROR(_xlfn.XLOOKUP(M:M,LOOKUP_TABLES!E:E,LOOKUP_TABLES!D:D),"Not Found") -> TechGlobal Ltd | M50: =IFERROR(INDEX(LOOKUP_TABLES!E:E,MATCH(B50,LOOKUP_TABLES!A:A,0)),"Not Found") -> 24 | N50: =_xlfn.XLOOKUP(B:B,LOOKUP_TABLES!A:A,LOOKUP_TABLES!F:F) -> SKU-1000
A52: TOTALS | C52: =SUM(C2:C50) -> 511 | G52: =SUM(G2:G50) -> 87166000 | H52: =SUM(H2:H50) -> 79038300 | I52: =SUM(I2:I50) -> 5927872.5 | J52: =SUM(J2:J50) -> 84966172

Sheet 📋 TASK_BRIEF
B1: 🏢 TECHBRIDGE NIGERIA LTD — EXCEL ANALYST PRACTICE WORKBOOK
B3: About TechBridge Nigeria Ltd
B4: TechBridge Nigeria Ltd is a Lagos-based technology distribution company operating across 4 regions (North, South, East, West). They sell consumer electronics and accessories via Online, In-Store, and Distributor channels. You have been hired as a Junior Data Analyst. Your manager has handed you raw sales data for FY2024 and wants a full report and dashboard by Friday.
B6: TASK 1 — Text to Columns
B7: RAW_DATA sheet → Column M ('Details') is pipe-delimited. Use Data > Text to Columns to split into 3 new columns: Product_Clean | Category_Clean | Channel_Clean.
B9: TASK 2 — Data Cleaning
B10: RAW_DATA: Fix typos in Region, Status, Channel, Product columns using Find & Replace. Remove exact duplicate rows (use Remove Duplicates). Handle blank cells with 'N/A'. Correct outlier Unit Prices (flag with conditional formatting — red fill if <1000 or >600000).
B12: TASK 3 — XLOOKUP Practice
B13: CALC_TABLE column K: Write an XLOOKUP to pull Category from LOOKUP_TABLES. The formula is already in the sheet — study it, then modify it to also pull SKU into a new column.
B15: TASK 4 — INDEX / MATCH
B16: CALC_TABLE column L: An INDEX/MATCH is already pulling Warranty months. Now write one to fetch the Supplier name from LOOKUP_TABLES into a new column.
B18: TASK 5 — IFERROR Handling
... B36: ⚠️ NOTE: The data contains intentional errors for practice — typos, duplicates, missing values, outliers, and future-dated orders. Cleaning them is part of the exercise!

Sheet LOOKUP_TABLES
A1: Product | B1: Category | C1: Standard Price (₦) | D1: Supplier | E1: Warranty (Months) | F1: SKU | H1: Sales Rep | I1: Target (₦) | J1: Region
A2: Laptop Pro | B2: Electronics | C2: 450000 | D2: TechGlobal Ltd | E2: 24 | F2: SKU-1000 | H2: James Okafor | I2: 11000000 | J2: North
A3: SmartPhone X | B3: Electronics | C3: 220000 | D3: MobileMaster NG | E3: 12 | F3: SKU-1001 | H3: Amaka Bello | I3: 14000000 | J3: South
A4: Tablet Air | B4: Electronics | C4: 180000 | D4: TechGlobal Ltd | E4: 12 | F4: SKU-1002 | H4: Chukwudi Eze | I4: 24000000 | J4: East
A5: Wireless Earbuds | B5: Accessories | C5: 35000 | D5: SoundWave Co | E5: 6 | F5: SKU-1003 | H5: Ngozi Adeyemi | I5: 20000000 | J5: West
A6: Monitor 4K | B6: Electronics | C6: 95000 | D6: VisualTech Ltd | E6: 24 | F6: SKU-1004 | H6: Emeka Nwosu | I6: 18000000 | J6: North
A7: Keyboard Mech | B7: Accessories | C7: 28000 | D7: InputPro NG | E7: 12 | F7: SKU-1005 | H7: Fatima Aliyu | I7: 25000000 | J7: South
A8: Mouse Ergo | B8: Accessories | C8: 18000 | D8: InputPro NG | E8: 12 | F8: SKU-1006 | H8: Ibrahim Musa | I8: 9000000 | J8: East
A9: Webcam HD | B9: Accessories | C9: 22000 | D9: SoundWave Co | E9: 12 | F9: SKU-1007 | H9: Kemi Adebayo | I9: 13000000 | J9: West
H10: Tunde Fashola | I10: 20000000 | J10: North
H11: Yemi Osinbajo | I11: 8000000 | J11: South

Sheet RAW_DATA
A1: Order ID | B1: Order Date | C1: Customer ID | D1: Sales Rep | E1: Region | F1: Product | G1: Category | H1: Channel | I1: Quantity | J1: Unit Price (₦) | K1: Discount (%) | L1: Status | M1: Details (Use Text-to-Columns)
A2: ORD-47512 | B2: 45434 | C2: CUST-4094 | D2: Yemi Osinbajo | E2: East | F2: Wireless Earbuds | G2: Accessories | H2: Distributor | I2: 7 | J2: 35000 | K2: 10 | L2: Pending | M2: Wireless Earbuds|Accessories|Distributor
A3: ORD-67431 | B3: 45464 | C3: CUST-1447 | D3: Fatima Aliyu | E3: North | F3: Mouse Ergo | G3: Accessories | H3: Distributor | I3: 4 | J3: 18000 | K3: 0 | L3: Completed | M3: Mouse Ergo|Accessories|Distributor
A4: ORD-89777 | B4: 45513 | C4: CUST-4674 | D4: James Okafor | E4: West | F4: Keyboard Mech | G4: Accessories | H4: Distributor | I4: 2 | J4: 28000 | K4: 15 | L4: Pending | M4: Keyboard Mech|Accessories|Distributor
A5: ORD-84141 | B5: 45573 | C5: CUST-1120 | D5: Fatima Aliyu | E5: West | F5: Webcam HD | G5: Accessories | H5: Distributor | I5: 1 | J5: 22000 | K5: 0 | L5: Completed | M5: Webcam HD|Accessories|Distributor
A6: ORD-72684 | B6: 45492 | C6: CUST-2977 | D6: Chukwudi Eze | E6: North | F6: Keyboard Mech | G6: Accessories | H6: In-Store | I6: 6 | J6: 28000 | K6: 0 | L6: Completed | M6: Keyboard Mech|Accessories|In-Store
A7: ORD-88636 | B7: 45604 | C7: CUST-1008 | D7: Fatima Aliyu | E7: South | F7: Mouse Ergo | G7: Accessories | H7: Online | I7: 4 | J7: 18000 | K7: 20 | L7: Completed | M7: Mouse Ergo|Accessories|Online
A8: ORD-98754 | B8: 45488 | C8: CUST-1949 | D8: Ngozi Adeyemi | E8: North | F8: Tablet Air | G8: Electronics | H8: In-Store | I8: 11 | J8: 180000 | K8: 10 | L8: Completed | M8: Tablet Air|Electronics|In-Store
A9: ORD-27224 | B9: 45547 | C9: CUST-3174 | D9: Emeka Nwosu | E9: East | F9: SmartPhone X | G9: Electronics | H9: Online | I9: 7 | J9: 220000 | K9: 0 | L9: Completed | M9: SmartPhone X|Electronics|Online
A10: ORD-64948 | B10: 45478 | C10: CUST-3751 | D10: Fatima Aliyu | E10: East | F10: Webcam HD | G10: Accessories | H10: In-Store | I10: 8 | J10: 22000 | K10: 0 | L10: Cancelled | M10: Webcam HD|Accessories|In-Store
A11: ORD-68459 | B11: 45491 | C11: CUST-2962 | F11: Tablet Air | G11: Electronics | H11: In-Store | I11: 10 | J11: 180000 | K11: 5 | L11: Pending | M11: Tablet Air|Electronics|In-Store
A12: ORD-26406 | B12: 45357 | C12: CUST-3698 | D12: Yemi Osinbajo | E12: North | F12: Laptop Pro | G12: Electronics | H12: Online | I12: 19 | J12: 450000 | K12: 10 | L12: Completed | M12: Laptop Pro|Electronics|Online
A13: ORD-99016 | B13: 45304 | C13: CUST-3424 | D13: Chukwudi Eze | E13: East | F13: Keyboard Mech | G13: Accessories | H13: Online | I13: 20 | J13: 28000 | K13: 10 | L13: Completed | M13: Keyboard Mech|Accessories|Online
A14: ORD-95800 | B14: 45652 | C14: CUST-2442 | D14: Emeka Nwosu | E14: East | F14: Monitor 4K | G14: Electronics | H14: Online | I14: 15 | J14: 95000 | K14: 0 | L14: Completed | M14: Monitor 4K|Electronics|Online
A15: ORD-94614 | B15: 45563 | C15: CUST-2531 | D15: Ngozi Adeyemi | E15: West | F15: SmartPhone X | G15: Electronics | H15: In-Store | I15: 16 | J15: 220000 | K15: 20 | L15: Completed | M15: SmartPhone X|Electronics|In-Store
A16: ORD-54350 | B16: 45483 | C16: CUST-2032 | D16: Fatima Aliyu | E16: North | F16: Laptop Pro | G16: Electronics | H16: Distributor | I16: 18 | J16: 450000 | K16: 15 | L16: Completed | M16: Laptop Pro|Electronics|Distributor
A17: ORD-53207 | B17: 45424 | C17: CUST-1424 | D17: Ibrahim Musa | E17: East | F17: SmartPhone X | G17: Electronics | I17: 10 | J17: 220000 | K17: 10 | L17: Completed | M17: SmartPhone X|Electronics|None
A18: ORD-49008 | B18: 45561 | C18: CUST-3955 | D18: Ngozi Adeyemi | E18: South | F18: Laptop Pro | G18: Electronics | H18: Online | I18: 16 | J18: 450000 | K18: 0 | L18: Cancelled | M18: Laptop Pro|Electronics|Online
A19: ORD-18357 | B19: 45376 | C19: CUST-1554 | D19: James Okafor | E19: North | F19: Webcam HD | G19: Accessories | H19: Online | I19: 10 | J19: 22000 | K19: 5 | L19: Completed | M19: Webcam HD|Accessories|Online
A20: ORD-25194 | B20: 45399 | C20: CUST-2481 | D20: Tunde Fashola | E20: East | F20: Keyboard Mech | G20: Accessories | H20: Online | I20: 14 | J20: 28000 | K20: 0 | L20: Completed | M20: Keyboard Mech|Accessories|Online
A21: ORD-13478 | B21: 45574 | C21: CUST-4315 | D21: Ngozi Adeyemi | E21: South | F21: Webcam HD | G21: Accessories | H21: In-Store | I21: 8 | J21: 22000 | K21: 5 | L21: Completed | M21: Webcam HD|Accessories|In-Store
A22: ORD-60940 | B22: 45631 | C22: CUST-4626 | D22: Fatima Aliyu | E22: South | F22: Mouse Ergo | G22: Accessories | H22: In-Store | I22: 19 | J22: 18000 | K22: 15 | L22: Completed | M22: Mouse Ergo|Accessories|In-Store
A23: ORD-77286 | B23: 45475 | C23: CUST-2623 | D23: Ibrahim Musa | E23: North | F23: Tablet Air | G23: Electronics | H23: In-Store | I23: 12 | J23: 180000 | K23: 0 | L23: Completed | M23: Tablet Air|Electronics|In-Store
A24: ORD-25194 | B24: 45399 | C24: CUST-2481 | D24: Tunde Fashola | E24: East | F24: Keyboard Mech | G24: Accessories | H24: Online | I24: 14 | J24: 28000 | K24: 0 | L24: Completed | M24: Keyboard Mech|Accessories|Online
A25: ORD-59131 | B25: 45357 | C25: CUST-1717 | D25: Chukwudi Eze | E25: South | F25: Keyboard Mech | G25: Accessories | H25: In-Store | I25: 19 | J25: 28000 | K25: 15 | L25: Completed | M25: Keyboard Mech|Accessories|In-Store
A26: ORD-77154 | B26: 45557 | C26: CUST-2263 | D26: Fatima Aliyu | E26: West | F26: SmartPhone X | G26: Electronics | H26: ONLINE | I26: 19 | J26: 220000 | K26: 5 | L26: Returned | M26: SmartPhone X|Electronics|ONLINE
A27: ORD-23173 | B27: 45301 | C27: CUST-2468 | D27: Chukwudi Eze | E27: South | F27: Mouse Ergo | G27: Accessories | H27: Distributor | I27: 2 | J27: 18000 | K27: 0 | L27: Completed | M27: Mouse Ergo|Accessories|Distributor
A28: ORD-87278 | B28: 45449 | C28: CUST-2238 | D28: Yemi Osinbajo | E28: East | F28: Webcam HD | G28: Accessories | H28: On-Line | I28: 10 | J28: 22000 | K28: 0 | L28: Pending | M28: Webcam HD|Accessories|On-Line
A29: ORD-96400 | B29: 45577 | C29: CUST-3999 | D29: Amaka Bello | E29: South | F29: Tablet Air | G29: Electronics | H29: Online | I29: 15 | J29: 180000 | K29: 0 | L29: Returned | M29: Tablet Air|Electronics|Online
... A46: ORD-58655 | B46: 45360 | C46: CUST-2840 | D46: Amaka Bello | E46: South | F46: Webcam HD | G46: Accessories | H46: In-Store | I46: 10 | J46: 22000 | K46: 0 | L46: Completed | M46: Webcam HD|Accessories|In-Store
A47: ORD-80075 | B47: 45416 | C47: CUST-2928 | E47: North | F47: Mouse Ergo | G47: Accessories | H47: Distributor | I47: 18 | J47: 18000 | K47: 0 | L47: Completed | M47: Mouse Ergo|Accessories|Distributor
A48: ORD-95969 | B48: 45609 | C48: CUST-3004 | D48: Chukwudi Eze | E48: South | F48: Tablet Air | G48: Electronics | H48: In-Store | I48: 8 | J48: 180000 | K48: 20 | L48: Cancelled | M48: Tablet Air|Electronics|In-Store
A49: ORD-20589 | B49: 45615 | C49: CUST-3246 | D49: Yemi Osinbajo | E49: south | F49: Monitor 4K | G49: Electronics | H49: online | I49: 9 | J49: 95000 | K49: 10 | L49: Compelted | M49: Monitor 4K|Electronics|online
A50: ORD-55143 | B50: 45479 | C50: CUST-4090 | D50: Tunde Fashola | E50: East | F50: Keyboard Mech | G50: Accessories | H50: Online | I50: 5 | J50: 28000 | K50: 0 | L50: Completed | M50: Keyboard Mech|Accessories|Online
A51: ORD-94803 | B51: 45295 | C51: CUST-2059 | D51: Yemi Osinbajo | E51: South | F51: Laptop Pro | G51: Electronics | H51: Online | I51: 14 | J51: 450000 | K51: 0 | L51: Cancelled | M51: Laptop Pro|Electronics|Online
A52: ORD-74340 | B52: 45449 | C52: CUST-4954 | D52: James Okafor | E52: North | F52: SmartPhone X | G52: Electronics | H52: Distributor | I52: 16 | J52: 220000 | K52: 5 | L52: Completed | M52: SmartPhone X|Electronics|Distributor
A53: ORD-35614 | B53: 45547 | C53: CUST-3604 | D53: Ngozi Adeyemi | E53: SOUTH | F53: Webcam HD | G53: Accessories | H53: online | I53: 1 | J53: 22000 | K53: 0 | L53: completed | M53: Webcam HD|Accessories|online
A54: ORD-91851 | B54: 45574 | C54: CUST-3667 | D54: Yemi Osinbajo | E54: North | F54: Monitor 4K | G54: Electronics | H54: Online | I54: 2 | J54: 95000 | K54: 15 | L54: Completed | M54: Monitor 4K|Electronics|Online
A55: ORD-62205 | B55: 45495 | C55: CUST-4672 | D55: Emeka Nwosu | E55: South | F55: SmartPhone X | G55: Electronics | H55: In-Store | I55: 19 | J55: 220000 | K55: 20 | L55: Pending | M55: SmartPhone X|Electronics|In-Store
A56: ORD-61374 | B56: 45622 | C56: CUST-2345 | D56: Yemi Osinbajo | E56: South | F56: Tablet Air | G56: Electronics | H56: Online | I56: 18 | J56: 180000 | K56: 5 | L56: Returned | M56: Tablet Air|Electronics|Online
...

Sheet CALC_TABLE
A1: Order ID | B1: Product | C1: Quantity | D1: Unit Price (₦) | E1: Discount (%) | F1: Status | G1: Revenue (₦) | H1: Discounted Revenue (₦) | I1: VAT 7.5% (₦) | J1: Net Revenue (₦) | K1: Category (XLOOKUP) | L1: Warranty (INDEX-MATCH)
A2: ORD-47512 | B2: Wireless Earbuds | C2: 7 | D2: 35000 | E2: 10 | F2: Pending | G2: =C2*D2 -> 245000 | H2: =G2*(1-E2/100) -> 220500 | I2: =H2*0.075 -> 16537.5 | J2: =H2+I2 -> 237037.5 | K2: =IFERROR(_xludf.xlookup(B2,LOOKUP_TABLES!A:A,LOOKUP_TABLES!B:B,"Not Found"),"Error") -> Error | L2: =IFERROR(INDEX(LOOKUP_TABLES!E:E,MATCH(B2,LOOKUP_TABLES!A:A,0)),"Not Found") -> 6
A3: ORD-67431 | B3: Mouse Ergo | C3: 4 | D3: 18000 | E3: 0 | F3: Completed | G3: =C3*D3 -> 72000 | H3: =G3*(1-E3/100) -> 72000 | I3: =H3*0.075 -> 5400 | J3: =H3+I3 -> 77400 | K3: =IFERROR(_xludf.xlookup(B3,LOOKUP_TABLES!A:A,LOOKUP_TABLES!B:B,"Not Found"),"Error") -> Error | L3: =IFERROR(INDEX(LOOKUP_TABLES!E:E,MATCH(B3,LOOKUP_TABLES!A:A,0)),"Not Found") -> 12
A4: ORD-89777 | B4: Keyboard Mech | C4: 2 | D4: 28000 | E4: 15 | F4: Pending | G4: =C4*D4 -> 56000 | H4: =G4*(1-E4/100) -> 47600 | I4: =H4*0.075 -> 3570 | J4: =H4+I4 -> 51170 | K4: =IFERROR(_xludf.xlookup(B4,LOOKUP_TABLES!A:A,LOOKUP_TABLES!B:B,"Not Found"),"Error") -> Error | L4: =IFERROR(INDEX(LOOKUP_TABLES!E:E,MATCH(B4,LOOKUP_TABLES!A:A,0)),"Not Found") -> 12
A5: ORD-84141 | B5: Webcam HD | C5: 1 | D5: 22000 | E5: 0 | F5: Completed | G5: =C5*D5 -> 22000 | H5: =G5*(1-E5/100) -> 22000 | I5: =H5*0.075 -> 1650 | J5: =H5+I5 -> 23650 | K5: =IFERROR(_xludf.xlookup(B5,LOOKUP_TABLES!A:A,LOOKUP_TABLES!B:B,"Not Found"),"Error") -> Error | L5: =IFERROR(INDEX(LOOKUP_TABLES!E:E,MATCH(B5,LOOKUP_TABLES!A:A,0)),"Not Found") -> 12
A6: ORD-72684 | B6: Keyboard Mech | C6: 6 | D6: 28000 | E6: 0 | F6: Completed | G6: =C6*D6 -> 168000 | H6: =G6*(1-E6/100) -> 168000 | I6: =H6*0.075 -> 12600 | J6: =H6+I6 -> 180600 | K6: =IFERROR(_xludf.xlookup(B6,LOOKUP_TABLES!A:A,LOOKUP_TABLES!B:B,"Not Found"),"Error") -> Error | L6: =IFERROR(INDEX(LOOKUP_TABLES!E:E,MATCH(B6,LOOKUP_TABLES!A:A,0)),"Not Found") -> 12
A7: ORD-88636 | B7: Mouse Ergo | C7: 4 | D7: 18000 | E7: 20 | F7: Completed | G7: =C7*D7 -> 72000 | H7: =G7*(1-E7/100) -> 57600 | I7: =H7*0.075 -> 4320 | J7: =H7+I7 -> 61920 | K7: =IFERROR(_xludf.xlookup(B7,LOOKUP_TABLES!A:A,LOOKUP_TABLES!B:B,"Not Found"),"Error") -> Error | L7: =IFERROR(INDEX(LOOKUP_TABLES!E:E,MATCH(B7,LOOKUP_TABLES!A:A,0)),"Not Found") -> 12
A8: ORD-98754 | B8: Tablet Air | C8: 11 | D8: 180000 | E8: 10 | F8: Completed | G8: =C8*D8 -> 1980000 | H8: =G8*(1-E8/100) -> 1782000 | I8: =H8*0.075 -> 133650 | J8: =H8+I8 -> 1915650 | K8: =IFERROR(_xludf.xlookup(B8,LOOKUP_TABLES!A:A,LOOKUP_TABLES!B:B,"Not Found"),"Error") -> Error | L8: =IFERROR(INDEX(LOOKUP_TABLES!E:E,MATCH(B8,LOOKUP_TABLES!A:A,0)),"Not Found") -> 12
A9: ORD-27224 | B9: SmartPhone X | C9: 7 | D9: 220000 | E9: 0 | F9: Completed | G9: =C9*D9 -> 1540000 | H9: =G9*(1-E9/100) -> 1540000 | I9: =H9*0.075 -> 115500 | J9: =H9+I9 -> 1655500 | K9: =IFERROR(_xludf.xlookup(B9,LOOKUP_TABLES!A:A,LOOKUP_TABLES!B:B,"Not Found"),"Error") -> Error | L9: =IFERROR(INDEX(LOOKUP_TABLES!E:E,MATCH(B9,LOOKUP_TABLES!A:A,0)),"Not Found") -> 12
A10: ORD-64948 | B10: Webcam HD | C10: 8 | D10: 22000 | E10: 0 | F10: Cancelled | G10: =C10*D10 -> 176000 | H10: =G10*(1-E10/100) -> 176000 | I10: =H10*0.075 -> 13200 | J10: =H10+I10 -> 189200 | K10: =IFERROR(_xludf.xlookup(B10,LOOKUP_TABLES!A:A,LOOKUP_TABLES!B:B,"Not Found"),"Error") -> Error | L10: =IFERROR(INDEX(LOOKUP_TABLES!E:E,MATCH(B10,LOOKUP_TABLES!A:A,0)),"Not Found") -> 12
A11: ORD-68459 | B11: Tablet Air | C11: 10 | D11: 180000 | E11: 5 | F11: Pending | G11: =C11*D11 -> 1800000 | H11: =G11*(1-E11/100) -> 1710000 | I11: =H11*0.075 -> 128250 | J11: =H11+I11 -> 1838250 | K11: =IFERROR(_xludf.xlookup(B11,LOOKUP_TABLES!A:A,LOOKUP_TABLES!B:B,"Not Found"),"Error") -> Error | L11: =IFERROR(INDEX(LOOKUP_TABLES!E:E,MATCH(B11,LOOKUP_TABLES!A:A,0)),"Not Found") -> 12
A12: ORD-26406 | B12: Laptop Pro | C12: 19 | D12: 450000 | E12: 10 | F12: Completed | G12: =C12*D12 -> 8550000 | H12: =G12*(1-E12/100) -> 7695000 | I12: =H12*0.075 -> 577125 | J12: =H12+I12 -> 8272125 | K12: =IFERROR(_xludf.xlookup(B12,LOOKUP_TABLES!A:A,LOOKUP_TABLES!B:B,"Not Found"),"Error") -> Error | L12: =IFERROR(INDEX(LOOKUP_TABLES!E:E,MATCH(B12,LOOKUP_TABLES!A:A,0)),"Not Found") -> 24
A13: ORD-99016 | B13: Keyboard Mech | C13: 20 | D13: 28000 | E13: 10 | F13: Completed | G13: =C13*D13 -> 560000 | H13: =G13*(1-E13/100) -> 504000 | I13: =H13*0.075 -> 37800 | J13: =H13+I13 -> 541800 | K13: =IFERROR(_xludf.xlookup(B13,LOOKUP_TABLES!A:A,LOOKUP_TABLES!B:B,"Not Found"),"Error") -> Error | L13: =IFERROR(INDEX(LOOKUP_TABLES!E:E,MATCH(B13,LOOKUP_TABLES!A:A,0)),"Not Found") -> 12
... A51: ORD-94803 | B51: Laptop Pro | C51: 14 | D51: 450000 | E51: 0 | F51: Cancelled | G51: =C51*D51 -> 6300000 | H51: =G51*(1-E51/100) -> 6300000 | I51: =H51*0.075 -> 472500 | J51: =H51+I51 -> 6772500 | K51: =IFERROR(_xludf.xlookup(B51,LOOKUP_TABLES!A:A,LOOKUP_TABLES!B:B,"Not Found"),"Error") -> Error | L51: =IFERROR(INDEX(LOOKUP_TABLES!E:E,MATCH(B51,LOOKUP_TABLES!A:A,0)),"Not Found") -> 24
A52: TOTALS | C52: =SUM(C2:C51) -> 525 | G52: =SUM(G2:G51) -> 87558000 | H52: =SUM(H2:H51) -> 79430300 | I52: =SUM(I2:I51) -> 5957272.5 | J52: =SUM(J2:J51) -> 85387572
